Workbook

Sheet 월별추이
A1: =설정!$B$4&"년 월별 수입·지출·저축 추이" -> 2025년 월별 수입·지출·저축 추이
A2: 각 월 시트에서 자동으로 가져옵니다 (입력 불필요)
A4: 월 | B4: 총 수입 | C4: 총 지출 | D4: 고정비 | E4: 변동비 | F4: 일반 저축 | G4: 대출상환 저축 | H4: 저축 합계 | I4: 저축률 | J4: 누적 일반 저축 | K4: 누적 대출상환 | L4: 누적 저축 합계
A5: 1월 | B5: =1월!$B$5 -> 7150000 | C5: =1월!$B$6 -> 4130000 | D5: =1월!$B$7 -> 2170000 | E5: =1월!$B$8 -> 1960000 | F5: =1월!$B$10 -> 3020000 | G5: =1월!$B$11 -> 0 | H5: =1월!$B$9 -> 3020000 | I5: =IF(B5=0,0,H5/B5) -> 0.42237762 | J5: =SUM($F$5:F5) -> 3020000 | K5: =SUM($G$5:G5) -> 0 | L5: =SUM($H$5:H5) -> 3020000
A6: 2월 | B6: =2월!$B$5 -> 9650000 | C6: =2월!$B$6 -> 4320000 | D6: =2월!$B$7 -> 2180000 | E6: =2월!$B$8 -> 2140000 | F6: =2월!$B$10 -> 5330000 | G6: =2월!$B$11 -> 1200000 | H6: =2월!$B$9 -> 6530000 | I6: =IF(B6=0,0,H6/B6) -> 0.67668394 | J6: =SUM($F$5:F6) -> 8350000 | K6: =SUM($G$5:G6) -> 1200000 | L6: =SUM($H$5:H6) -> 9550000
A7: 3월 | B7: =3월!$B$5 -> 7150000 | C7: =3월!$B$6 -> 4400000 | D7: =3월!$B$7 -> 2240000 | E7: =3월!$B$8 -> 2160000 | F7: =3월!$B$10 -> 2750000 | G7: =3월!$B$11 -> 1200000 | H7: =3월!$B$9 -> 3950000 | I7: =IF(B7=0,0,H7/B7) -> 0.55244755 | J7: =SUM($F$5:F7) -> 11100000 | K7: =SUM($G$5:G7) -> 2400000 | L7: =SUM($H$5:H7) -> 13500000
A8: 4월 | B8: =4월!$B$5 -> 7650000 | C8: =4월!$B$6 -> 4340000 | D8: =4월!$B$7 -> 2190000 | E8: =4월!$B$8 -> 2150000 | F8: =4월!$B$10 -> 3310000 | G8: =4월!$B$11 -> 1200000 | H8: =4월!$B$9 -> 4510000 | I8: =IF(B8=0,0,H8/B8) -> 0.58954248 | J8: =SUM($F$5:F8) -> 14410000 | K8: =SUM($G$5:G8) -> 3600000 | L8: =SUM($H$5:H8) -> 18010000
A9: 5월 | B9: =5월!$B$5 -> 7650000 | C9: =5월!$B$6 -> 4220000 | D9: =5월!$B$7 -> 2260000 | E9: =5월!$B$8 -> 1960000 | F9: =5월!$B$10 -> 3430000 | G9: =5월!$B$11 -> 1200000 | H9: =5월!$B$9 -> 4630000 | I9: =IF(B9=0,0,H9/B9) -> 0.60522876 | J9: =SUM($F$5:F9) -> 17840000 | K9: =SUM($G$5:G9) -> 4800000 | L9: =SUM($H$5:H9) -> 22640000
A10: 6월 | B10: =6월!$B$5 -> 7150000 | C10: =6월!$B$6 -> 4390000 | D10: =6월!$B$7 -> 2290000 | E10: =6월!$B$8 -> 2100000 | F10: =6월!$B$10 -> 2760000 | G10: =6월!$B$11 -> 1190000 | H10: =6월!$B$9 -> 3950000 | I10: =IF(B10=0,0,H10/B10) -> 0.55244755 | J10: =SUM($F$5:F10) -> 20600000 | K10: =SUM($G$5:G10) -> 5990000 | L10: =SUM($H$5:H10) -> 26590000
A11: 7월 | B11: =7월!$B$5 -> 7650000 | C11: =7월!$B$6 -> 4310000 | D11: =7월!$B$7 -> 2180000 | E11: =7월!$B$8 -> 2130000 | F11: =7월!$B$10 -> 3340000 | G11: =7월!$B$11 -> 1210000 | H11: =7월!$B$9 -> 4550000 | I11: =IF(B11=0,0,H11/B11) -> 0.59477124 | J11: =SUM($F$5:F11) -> 23940000 | K11: =SUM($G$5:G11) -> 7200000 | L11: =SUM($H$5:H11) -> 31140000
A12: 8월 | B12: =8월!$B$5 -> 7150000 | C12: =8월!$B$6 -> 4150000 | D12: =8월!$B$7 -> 2280000 | E12: =8월!$B$8 -> 1870000 | F12: =8월!$B$10 -> 3000000 | G12: =8월!$B$11 -> 1200000 | H12: =8월!$B$9 -> 4200000 | I12: =IF(B12=0,0,H12/B12) -> 0.58741259 | J12: =SUM($F$5:F12) -> 26940000 | K12: =SUM($G$5:G12) -> 8400000 | L12: =SUM($H$5:H12) -> 35340000
A13: 9월 | B13: =9월!$B$5 -> 9350000 | C13: =9월!$B$6 -> 4910000 | D13: =9월!$B$7 -> 2250000 | E13: =9월!$B$8 -> 2660000 | F13: =9월!$B$10 -> 4440000 | G13: =9월!$B$11 -> 1200000 | H13: =9월!$B$9 -> 5640000 | I13: =IF(B13=0,0,H13/B13) -> 0.60320856 | J13: =SUM($F$5:F13) -> 31380000 | K13: =SUM($G$5:G13) -> 9600000 | L13: =SUM($H$5:H13) -> 40980000
A14: 10월 | B14: =10월!$B$5 -> 7150000 | C14: =10월!$B$6 -> 4460000 | D14: =10월!$B$7 -> 2290000 | E14: =10월!$B$8 -> 2170000 | F14: =10월!$B$10 -> 2690000 | G14: =10월!$B$11 -> 1200000 | H14: =10월!$B$9 -> 3890000 | I14: =IF(B14=0,0,H14/B14) -> 0.54405594 | J14: =SUM($F$5:F14) -> 34070000 | K14: =SUM($G$5:G14) -> 10800000 | L14: =SUM($H$5:H14) -> 44870000
A15: 11월 | B15: =11월!$B$5 -> 7650000 | C15: =11월!$B$6 -> 4310000 | D15: =11월!$B$7 -> 2230000 | E15: =11월!$B$8 -> 2080000 | F15: =11월!$B$10 -> 3340000 | G15: =11월!$B$11 -> 1200000 | H15: =11월!$B$9 -> 4540000 | I15: =IF(B15=0,0,H15/B15) -> 0.59346405 | J15: =SUM($F$5:F15) -> 37410000 | K15: =SUM($G$5:G15) -> 12000000 | L15: =SUM($H$5:H15) -> 49410000
A16: 12월 | B16: =12월!$B$5 -> 7650000 | C16: =12월!$B$6 -> 4500000 | D16: =12월!$B$7 -> 2230000 | E16: =12월!$B$8 -> 2270000 | F16: =12월!$B$10 -> 3150000 | G16: =12월!$B$11 -> 1200000 | H16: =12월!$B$9 -> 4350000 | I16: =IF(B16=0,0,H16/B16) -> 0.56862745 | J16: =SUM($F$5:F16) -> 40560000 | K16: =SUM($G$5:G16) -> 13200000 | L16: =SUM($H$5:H16) -> 53760000
A17: 합계 | B17: =SUM(B5:B16) -> 93000000 | C17: =SUM(C5:C16) -> 52440000 | D17: =SUM(D5:D16) -> 26790000 | E17: =SUM(E5:E16) -> 25650000 | F17: =SUM(F5:F16) -> 40560000 | G17: =SUM(G5:G16) -> 13200000 | H17: =SUM(H5:H16) -> 53760000 | I17: =IF(B17=0,0,H17/B17) -> 0.57806452 | J17: =F17 -> 40560000 | K17: =G17 -> 13200000 | L17: =H17 -> 53760000
A18: 월평균(입력월) | B18: =IFERROR(AVERAGEIF($B$5:$B$16,">0",B5:B16),0) -> 7750000 | C18: =IFERROR(AVERAGEIF($B$5:$B$16,">0",C5:C16),0) -> 4370000 | D18: =IFERROR(AVERAGEIF($B$5:$B$16,">0",D5:D16),0) -> 2232500 | E18: =IFERROR(AVERAGEIF($B$5:$B$16,">0",E5:E16),0) -> 2137500 | F18: =IFERROR(AVERAGEIF($B$5:$B$16,">0",F5:F16),0) -> 3380000 | G18: =IFERROR(AVERAGEIF($B$5:$B$16,">0",G5:G16),0) -> 1100000 | H18: =IFERROR(AVERAGEIF($B$5:$B$16,">0",H5:H16),0) -> 4480000 | I18: =IF(B18=0,0,H18/B18) -> 0.57806452
A19: 저축 비중 | F19: =IF($H$17=0,0,F17/$H$17) -> 0.75446429 | G19: =IF($H$17=0,0,G17/$H$17) -> 0.24553571
A20: 저축 비중: 연간 저축 합계 중 일반 저축 / 대출상환 저축이 차지하는 비율

Sheet 자산관리
A1: =설정!$B$4&"년 자산관리" -> 2025년 자산관리
A2: 매월 말 기준 잔액을 노란 칸에 입력하세요. 부채는 양수로 입력합니다.
A4: 1월 대비 현재 | D4: 오늘 기준월 | E4: =IF(YEAR(TODAY())>설정!$B$4,12,IF(YEAR(TODAY())<설정!$B$4,0,MONTH(TODAY()))) -> 12 | F4: 표시월 | G4: =SUMPRODUCT(MAX(((($D$28:$O$28<>0)+($D$29:$O$29<>0))>0)*(COLUMN($D$28:$O$28)-COLUMN($D$28)+1)*((COLUMN($D$28:$O$28)-COLUMN($D$28)+1)<=$E$4))) -> 12
A5: 구분 | D5: 1월 | E5: ="현재 ("&$G$4&"월)" -> 현재 (12월) | F5: 증감액 | G5: 증가율 | H5: =IF(AND($E$4>0,$G$4<$E$4),$E$4&"월 자산 미입력 → "&$G$4&"월 기준으로 표시","")
A6: 총자산 | D6: =$D$28 -> 780730000 | E6: =IF($G$4=0,0,INDEX($D$28:$O$28,$G$4)) -> 872010000 | F6: =IF(OR($G$4<2,D6=0),"",E6-D6) -> 91280000 | G6: =IF(OR($G$4<2,D6=0),"",(E6-D6)/ABS(D6)) -> 0.11691622 | H6: 매일 오늘 날짜 기준으로 자동 갱신 · 1월 값이 없거나 2월 이후 입력이 없으면 비워 둡니다
A7: 순자산 | D7: =$D$30 -> 446330000 | E7: =IF($G$4=0,0,INDEX($D$30:$O$30,$G$4)) -> 550810000 | F7: =IF(OR($G$4<2,D7=0),"",E7-D7) -> 104480000 | G7: =IF(OR($G$4<2,D7=0),"",(E7-D7)/ABS(D7)) -> 0.23408689
A8: 대분류 | B8: 중분류 | C8: 소분류 | D8: 1월 | E8: 2월 | F8: 3월 | G8: 4월 | H8: 5월 | I8: 6월 | J8: 7월 | K8: 8월 | L8: 9월 | M8: 10월 | N8: 11월 | O8: 12월
A9: 유동자산 | B9: 저축 | C9: 현금 | D9: 11000000 | E9: 11260000 | F9: 11980000 | G9: 12100000 | H9: 12600000 | I9: 12690000 | J9: 13060000 | K9: 13610000 | L9: 13840000 | M9: 14210000 | N9: 14450000 | O9: 14930000
A10: 유동자산 | B10: 저축 | C10: 복지포인트 | D10: 370000 | E10: 390000 | F10: 400000 | G10: 400000 | H10: 420000 | I10: 430000 | J10: 440000 | K10: 450000 | L10: 460000 | M10: 480000 | N10: 490000 | O10: 490000
A11: 유동자산 | B11: 저축 | C11: 예비현금 | D11: 3700000 | E11: 3860000 | F11: 3980000 | G11: 4120000 | H11: 4160000 | I11: 4210000 | J11: 4450000 | K11: 4560000 | L11: 4620000 | M11: 4720000 | N11: 4830000 | O11: 4990000
A12: 유동자산 | B12: 투자 | C12: 참주식 | D12: 58740000 | E12: 60360000 | F12: 64130000 | G12: 63860000 | H12: 67380000 | I12: 68880000 | J12: 71030000 | K12: 72950000 | L12: 72800000 | M12: 76260000 | N12: 76200000 | O12: 78300000
A13: 유동자산 | B13: 투자 | C13: 정윤주식 | D13: 22340000 | E13: 22530000 | F13: 23820000 | G13: 24720000 | H13: 25090000 | I13: 25680000 | J13: 26270000 | K13: 27240000 | L13: 27310000 | M13: 28170000 | N13: 29420000 | O13: 29420000
A14: 유동자산 | B14: 투자 | C14: 비트코인 | D14: 7350000 | E14: 7740000 | F14: 7730000 | G14: 8110000 | H14: 8470000 | I14: 8480000 | J14: 8720000 | K14: 9100000 | L14: 9150000 | M14: 9460000 | N14: 9690000 | O14: 9760000
A15: 비유동자산 | B15: 부동산 | C15: 아파트 | D15: 614250000 | E15: 617500000 | F15: 620750000 | G15: 624000000 | H15: 627250000 | I15: 630500000 | J15: 633750000 | K15: 637000000 | L15: 640250000 | M15: 643500000 | N15: 646750000 | O15: 650000000
A16: 비유동자산 | B16: 퇴직금 | C16: 참퇴직금 | D16: 29590000 | E16: 30780000 | F16: 30970000 | G16: 32030000 | H16: 33760000 | I16: 34380000 | J16: 34600000 | K16: 35670000 | L16: 36810000 | M16: 37640000 | N16: 38690000 | O16: 39830000
A17: 비유동자산 | B17: 퇴직금 | C17: 정윤퇴직금 | D17: 18730000 | E17: 19020000 | F17: 19610000 | G17: 19880000 | H17: 20660000 | I17: 21630000 | J17: 21610000 | K17: 22500000 | L17: 22840000 | M17: 23820000 | N17: 23960000 | O17: 24720000
A18: 비유동자산 | B18: 청약 | C18: 참청약 | D18: 8830000 | E18: 9320000 | F18: 9310000 | G18: 9760000 | H18: 10030000 | I18: 10400000 | J18: 10520000 | K18: 10950000 | L18: 10910000 | M18: 11370000 | N18: 11760000 | O18: 11720000
A19: 비유동자산 | B19: 청약 | C19: 정윤청약 | D19: 5830000 | E19: 6140000 | F19: 6280000 | G19: 6530000 | H19: 6580000 | I19: 6830000 | J19: 7070000 | K19: 7160000 | L19: 7290000 | M19: 7460000 | N19: 7660000 | O19: 7850000
A20: 부채 | B20: 대출 | C20: 주택담보대출 | D20: 313500000 | E20: 312380000 | F20: 311250000 | G20: 310120000 | H20: 309000000 | I20: 307880000 | J20: 306750000 | K20: 305620000 | L20: 304500000 | M20: 303380000 | N20: 302250000 | O20: 301120000
... A22: 부채 | B22: 대출 | C22: 사내대출 | D22: 20900000 | E22: 20820000 | F22: 20750000 | G22: 20680000 | H22: 20600000 | I22: 20530000 | J22: 20450000 | K22: 20380000 | L22: 20300000 | M22: 20220000 | N22: 20150000 | O22: 20080000
A23: ▲ 항목 추가 시 이 행 위에 행 삽입
A25: 요약 | D25: 1월 | E25: 2월 | F25: 3월 | G25: 4월 | H25: 5월 | I25: 6월 | J25: 7월 | K25: 8월 | L25: 9월 | M25: 10월 | N25: 11월 | O25: 12월
A26: 유동자산 합계 | D26: =SUMIF($A$9:$A$23,"유동자산",D$9:D$23) -> 103500000 | E26: =SUMIF($A$9:$A$23,"유동자산",E$9:E$23) -> 106140000 | F26: =SUMIF($A$9:$A$23,"유동자산",F$9:F$23) -> 112040000 | G26: =SUMIF($A$9:$A$23,"유동자산",G$9:G$23) -> 113310000 | H26: =SUMIF($A$9:$A$23,"유동자산",H$9:H$23) -> 118120000 | I26: =SUMIF($A$9:$A$23,"유동자산",I$9:I$23) -> 120370000 | J26: =SUMIF($A$9:$A$23,"유동자산",J$9:J$23) -> 123970000 | K26: =SUMIF($A$9:$A$23,"유동자산",K$9:K$23) -> 127910000 | ... O26: =SUMIF($A$9:$A$23,"유동자산",O$9:O$23) -> 137890000
A27: 비유동자산 합계 | D27: =SUMIF($A$9:$A$23,"비유동자산",D$9:D$23) -> 677230000 | E27: =SUMIF($A$9:$A$23,"비유동자산",E$9:E$23) -> 682760000 | F27: =SUMIF($A$9:$A$23,"비유동자산",F$9:F$23) -> 686920000 | G27: =SUMIF($A$9:$A$23,"비유동자산",G$9:G$23) -> 692200000 | H27: =SUMIF($A$9:$A$23,"비유동자산",H$9:H$23) -> 698280000 | I27: =SUMIF($A$9:$A$23,"비유동자산",I$9:I$23) -> 703740000 | J27: =SUMIF($A$9:$A$23,"비유동자산",J$9:J$23) -> 707550000 | K27: =SUMIF($A$9:$A$23,"비유동자산",K$9:K$23) -> 713280000 | ... O27: =SUMIF($A$9:$A$23,"비유동자산",O$9:O$23) -> 734120000
A28: 총자산 | D28: =D26+D27 -> 780730000 | E28: =E26+E27 -> 788900000 | F28: =F26+F27 -> 798960000 | G28: =G26+G27 -> 805510000 | H28: =H26+H27 -> 816400000 | I28: =I26+I27 -> 824110000 | J28: =J26+J27 -> 831520000 | K28: =K26+K27 -> 841190000 | ... O28: =O26+O27 -> 872010000
A29: 부채 합계 | D29: =SUMIF($A$9:$A$23,"부채",D$9:D$23) -> 334400000 | E29: =SUMIF($A$9:$A$23,"부채",E$9:E$23) -> 333200000 | F29: =SUMIF($A$9:$A$23,"부채",F$9:F$23) -> 332000000 | G29: =SUMIF($A$9:$A$23,"부채",G$9:G$23) -> 330800000 | H29: =SUMIF($A$9:$A$23,"부채",H$9:H$23) -> 329600000 | I29: =SUMIF($A$9:$A$23,"부채",I$9:I$23) -> 328410000 | J29: =SUMIF($A$9:$A$23,"부채",J$9:J$23) -> 327200000 | K29: =SUMIF($A$9:$A$23,"부채",K$9:K$23) -> 326000000 | ... O29: =SUMIF($A$9:$A$23,"부채",O$9:O$23) -> 321200000
A30: 순자산 | D30: =D28-D29 -> 446330000 | E30: =E28-E29 -> 455700000 | F30: =F28-F29 -> 466960000 | G30: =G28-G29 -> 474710000 | H30: =H28-H29 -> 486800000 | I30: =I28-I29 -> 495700000 | J30: =J28-J29 -> 504320000 | K30: =K28-K29 -> 515190000 | ... O30: =O28-O29 -> 550810000
A31: 부채비율 (부채/총자산) | D31: =IF(D28=0,0,D29/D28) -> 0.42831709 | E31: =IF(E28=0,0,E29/E28) -> 0.42236025 | F31: =IF(F28=0,0,F29/F28) -> 0.4155402 | G31: =IF(G28=0,0,G29/G28) -> 0.4106715 | H31: =IF(H28=0,0,H29/H28) -> 0.40372366 | I31: =IF(I28=0,0,I29/I28) -> 0.39850263 | J31: =IF(J28=0,0,J29/J28) -> 0.39349625 | K31: =IF(K28=0,0,K29/K28) -> 0.38754621 | ... O31: =IF(O28=0,0,O29/O28) -> 0.3683444
A32: 전월 대비 총자산 증감 | E32: =IF(OR(COUNT(E$9:E$23)=0,COUNT(D$9:D$23)=0),"",E28-D28) -> 8170000 | F32: =IF(OR(COUNT(F$9:F$23)=0,COUNT(E$9:E$23)=0),"",F28-E28) -> 10060000 | G32: =IF(OR(COUNT(G$9:G$23)=0,COUNT(F$9:F$23)=0),"",G28-F28) -> 6550000 | H32: =IF(OR(COUNT(H$9:H$23)=0,COUNT(G$9:G$23)=0),"",H28-G28) -> 10890000 | I32: =IF(OR(COUNT(I$9:I$23)=0,COUNT(H$9:H$23)=0),"",I28-H28) -> 7710000 | J32: =IF(OR(COUNT(J$9:J$23)=0,COUNT(I$9:I$23)=0),"",J28-I28) -> 7410000 | K32: =IF(OR(COUNT(K$9:K$23)=0,COUNT(J$9:J$23)=0),"",K28-J28) -> 9670000 | L32: =IF(OR(COUNT(L$9:L$23)=0,COUNT(K$9:K$23)=0),"",L28-K28) -> 5090000 | ... O32: =IF(OR(COUNT(O$9:O$23)=0,COUNT(N$9:N$23)=0),"",O28-N28) -> 8110000
A33: 총자산 증감률 | E33: =IF(OR(E32="",D28=0),"",E32/D28) -> 0.010464565 | F33: =IF(OR(F32="",E28=0),"",F32/E28) -> 0.012751933 | G33: =IF(OR(G32="",F28=0),"",G32/F28) -> 0.0081981576 | H33: =IF(OR(H32="",G28=0),"",H32/G28) -> 0.013519385 | I33: =IF(OR(I32="",H28=0),"",I32/H28) -> 0.0094439 | J33: =IF(OR(J32="",I28=0),"",J32/I28) -> 0.0089915181 | K33: =IF(OR(K32="",J28=0),"",K32/J28) -> 0.011629305 | L33: =IF(OR(L32="",K28=0),"",L32/K28) -> 0.0060509516 | ... O33: =IF(OR(O32="",N28=0),"",O32/N28) -> 0.0093876606
A34: 전월 대비 순자산 증감 | E34: =IF(OR(COUNT(E$9:E$23)=0,COUNT(D$9:D$23)=0),"",E30-D30) -> 9370000 | F34: =IF(OR(COUNT(F$9:F$23)=0,COUNT(E$9:E$23)=0),"",F30-E30) -> 11260000 | G34: =IF(OR(COUNT(G$9:G$23)=0,COUNT(F$9:F$23)=0),"",G30-F30) -> 7750000 | H34: =IF(OR(COUNT(H$9:H$23)=0,COUNT(G$9:G$23)=0),"",H30-G30) -> 12090000 | I34: =IF(OR(COUNT(I$9:I$23)=0,COUNT(H$9:H$23)=0),"",I30-H30) -> 8900000 | J34: =IF(OR(COUNT(J$9:J$23)=0,COUNT(I$9:I$23)=0),"",J30-I30) -> 8620000 | K34: =IF(OR(COUNT(K$9:K$23)=0,COUNT(J$9:J$23)=0),"",K30-J30) -> 10870000 | L34: =IF(OR(COUNT(L$9:L$23)=0,COUNT(K$9:K$23)=0),"",L30-K30) -> 6290000 | ... O34: =IF(OR(COUNT(O$9:O$23)=0,COUNT(N$9:N$23)=0),"",O30-N30) -> 9310000
A35: 순자산 증감률 (수익률) | E35: =IF(OR(E34="",D30=0),"",E34/D30) -> 0.020993435 | F35: =IF(OR(F34="",E30=0),"",F34/E30) -> 0.024709239 | G35: =IF(OR(G34="",F30=0),"",G34/F30) -> 0.016596711 | H35: =IF(OR(H34="",G30=0),"",H34/G30) -> 0.025468181 | I35: =IF(OR(I34="",H30=0),"",I34/H30) -> 0.018282662 | J35: =IF(OR(J34="",I30=0),"",J34/I30) -> 0.01738955 | K35: =IF(OR(K34="",J30=0),"",K34/J30) -> 0.021553775 | L35: =IF(OR(L34="",K30=0),"",L34/K30) -> 0.012209088 | ... O35: =IF(OR(O34="",N30=0),"",O34/N30) -> 0.017192982
A36: 이번 달 일반 저축 (가계부) | D36: =1월!$B$10 -> 3020000 | E36: =2월!$B$10 -> 5330000 | F36: =3월!$B$10 -> 2750000 | G36: =4월!$B$10 -> 3310000 | H36: =5월!$B$10 -> 3430000 | I36: =6월!$B$10 -> 2760000 | J36: =7월!$B$10 -> 3340000 | K36: =8월!$B$10 -> 3000000 | L36: =9월!$B$10 -> 4440000 | M36: =10월!$B$10 -> 2690000 | N36: =11월!$B$10 -> 3340000 | O36: =12월!$B$10 -> 3150000
A37: 이번 달 대출상환 저축 | D37: =1월!$B$11 -> 0 | E37: =2월!$B$11 -> 1200000 | F37: =3월!$B$11 -> 1200000 | G37: =4월!$B$11 -> 1200000 | H37: =5월!$B$11 -> 1200000 | I37: =6월!$B$11 -> 1190000 | J37: =7월!$B$11 -> 1210000 | K37: =8월!$B$11 -> 1200000 | L37: =9월!$B$11 -> 1200000 | M37: =10월!$B$11 -> 1200000 | N37: =11월!$B$11 -> 1200000 | O37: =12월!$B$11 -> 1200000
A38: 이번 달 저축 합계 | D38: =D36+D37 -> 3020000 | E38: =E36+E37 -> 6530000 | F38: =F36+F37 -> 3950000 | G38: =G36+G37 -> 4510000 | H38: =H36+H37 -> 4630000 | I38: =I36+I37 -> 3950000 | J38: =J36+J37 -> 4550000 | K38: =K36+K37 -> 4200000 | ... O38: =O36+O37 -> 4350000
A39: 저축 외 자산 변동 (투자손익 등) | E39: =IF(E34="","",E34-E38) -> 2840000 | F39: =IF(F34="","",F34-F38) -> 7310000 | G39: =IF(G34="","",G34-G38) -> 3240000 | H39: =IF(H34="","",H34-H38) -> 7460000 | I39: =IF(I34="","",I34-I38) -> 4950000 | J39: =IF(J34="","",J34-J38) -> 4070000 | K39: =IF(K34="","",K34-K38) -> 6670000 | L39: =IF(L34="","",L34-L38) -> 650000 | ... O39: =IF(O34="","",O34-O38) -> 4960000
A40: 저축 제외 수익률 | E40: =IF(OR(E39="",D30=0),"",E39/D30) -> 0.006363005 | F40: =IF(OR(F39="",E30=0),"",F39/E30) -> 0.016041255 | G40: =IF(OR(G39="",F30=0),"",G39/F30) -> 0.0069384958 | H40: =IF(OR(H39="",G30=0),"",H39/G30) -> 0.015714857 | I40: =IF(OR(I39="",H30=0),"",I39/H30) -> 0.010168447 | J40: =IF(OR(J39="",I30=0),"",J39/I30) -> 0.0082106113 | K40: =IF(OR(K39="",J30=0),"",K39/J30) -> 0.01322573 | L40: =IF(OR(L39="",K30=0),"",L39/K30) -> 0.0012616705 | ... O40: =IF(OR(O39="",N30=0),"",O39/N30) -> 0.0091597415
A42: 대분류 | B42: 중분류 | D42: 1월 | E42: 2월 | F42: 3월 | G42: 4월 | H42: 5월 | I42: 6월 | J42: 7월 | K42: 8월 | L42: 9월 | M42: 10월 | N42: 11월 | O42: 12월
A43: 유동자산 | B43: 저축 | D43: =SUMIFS(D$9:D$23,$A$9:$A$23,$A43,$B$9:$B$23,$B43) -> 15070000 | E43: =SUMIFS(E$9:E$23,$A$9:$A$23,$A43,$B$9:$B$23,$B43) -> 15510000 | F43: =SUMIFS(F$9:F$23,$A$9:$A$23,$A43,$B$9:$B$23,$B43) -> 16360000 | G43: =SUMIFS(G$9:G$23,$A$9:$A$23,$A43,$B$9:$B$23,$B43) -> 16620000 | H43: =SUMIFS(H$9:H$23,$A$9:$A$23,$A43,$B$9:$B$23,$B43) -> 17180000 | I43: =SUMIFS(I$9:I$23,$A$9:$A$23,$A43,$B$9:$B$23,$B43) -> 17330000 | J43: =SUMIFS(J$9:J$23,$A$9:$A$23,$A43,$B$9:$B$23,$B43) -> 17950000 | K43: =SUMIFS(K$9:K$23,$A$9:$A$23,$A43,$B$9:$B$23,$B43) -> 18620000 | ... O43: =SUMIFS(O$9:O$23,$A$9:$A$23,$A43,$B$9:$B$23,$B43) -> 20410000
A44: 유동자산 | B44: 투자 | D44: =SUMIFS(D$9:D$23,$A$9:$A$23,$A44,$B$9:$B$23,$B44) -> 88430000 | E44: =SUMIFS(E$9:E$23,$A$9:$A$23,$A44,$B$9:$B$23,$B44) -> 90630000 | F44: =SUMIFS(F$9:F$23,$A$9:$A$23,$A44,$B$9:$B$23,$B44) -> 95680000 | G44: =SUMIFS(G$9:G$23,$A$9:$A$23,$A44,$B$9:$B$23,$B44) -> 96690000 | H44: =SUMIFS(H$9:H$23,$A$9:$A$23,$A44,$B$9:$B$23,$B44) -> 100940000 | I44: =SUMIFS(I$9:I$23,$A$9:$A$23,$A44,$B$9:$B$23,$B44) -> 103040000 | J44: =SUMIFS(J$9:J$23,$A$9:$A$23,$A44,$B$9:$B$23,$B44) -> 106020000 | K44: =SUMIFS(K$9:K$23,$A$9:$A$23,$A44,$B$9:$B$23,$B44) -> 109290000 | ... O44: =SUMIFS(O$9:O$23,$A$9:$A$23,$A44,$B$9:$B$23,$B44) -> 117480000
...

Sheet 1월
A1: =설정!$B$4&"년 1월 가계부" -> 2025년 1월 가계부
A2: 노란 칸에 금액을 입력하세요. 저축 합계 = 일반 저축(수입 − 지출) + 대출상환 저축(자산관리 시트 부채 감소분, 자동)
A4: 요약 | B4: 금액 | D4: 그래프 데이터
A5: 총 수입 | B5: =SUMIF($A$15:$A$27,"수입",$C$15:$C$27) -> 7150000 | D5: 고정비 | E5: =B7 -> 2170000
A6: 총 지출 | B6: =B7+B8 -> 4130000 | D6: 변동비 | E6: =B8 -> 1960000
A7: 고정비 | B7: =SUMIF($A$15:$A$27,"고정비",$C$15:$C$27) -> 2170000 | D7: 일반저축 | E7: =MAX(B10,0) -> 3020000
A8: 변동비 | B8: =SUMIF($A$15:$A$27,"변동비",$C$15:$C$27) -> 1960000
A9: 저축 합계 | B9: =B10+B11 -> 3020000 | D9: 일반 저축 | E9: =MAX(B10,0) -> 3020000
A10: 일반 저축 (수입−지출) | B10: =B5-B6 -> 3020000 | D10: 대출상환 저축 | E10: =B11 -> 0
A11: 대출상환 저축 (부채 감소) | B11: =IF(AND(COUNT(자산관리!D$9:D$23)>0,설정!$B$5<>""),MAX(0,설정!$B$5-자산관리!D$29),0) -> 0
A12: 저축률 | B12: =IF(B5=0,0,B9/B5) -> 0.42237762
A14: 구분(1차) | B14: 항목(2차) | C14: 금액 | D14: 메모
A15: 수입 | B15: 참월급 | C15: 4000000
A16: 수입 | B16: 정윤월급 | C16: 3150000
A17: 수입 | B17: 기타수입 | C17: 0
A18: 고정비 | B18: 주거비 | C18: 1250000
A19: 고정비 | B19: 용돈 | C19: 600000
A20: 고정비 | B20: 관리비 | C20: 200000
A21: 고정비 | B21: 통신 | C21: 120000
A22: 변동비 | B22: 할부금 | C22: 300000
A23: 변동비 | B23: 생활비 | C23: 1360000
A24: 변동비 | B24: 초과금 | C24: 100000
A25: 변동비 | B25: 의료비 | C25: 80000
A26: 변동비 | B26: 기타 | C26: 120000
A27: ▲ 항목 추가 시 이 행 위에 행 삽입

Sheet 2월
A1: =설정!$B$4&"년 2월 가계부" -> 2025년 2월 가계부
A2: 노란 칸에 금액을 입력하세요. 저축 합계 = 일반 저축(수입 − 지출) + 대출상환 저축(자산관리 시트 부채 감소분, 자동)
A4: 요약 | B4: 금액 | D4: 그래프 데이터
A5: 총 수입 | B5: =SUMIF($A$15:$A$27,"수입",$C$15:$C$27) -> 9650000 | D5: 고정비 | E5: =B7 -> 2180000
A6: 총 지출 | B6: =B7+B8 -> 4320000 | D6: 변동비 | E6: =B8 -> 2140000
A7: 고정비 | B7: =SUMIF($A$15:$A$27,"고정비",$C$15:$C$27) -> 2180000 | D7: 일반저축 | E7: =MAX(B10,0) -> 5330000
A8: 변동비 | B8: =SUMIF($A$15:$A$27,"변동비",$C$15:$C$27) -> 2140000
A9: 저축 합계 | B9: =B10+B11 -> 6530000 | D9: 일반 저축 | E9: =MAX(B10,0) -> 5330000
A10: 일반 저축 (수입−지출) | B10: =B5-B6 -> 5330000 | D10: 대출상환 저축 | E10: =B11 -> 1200000
A11: 대출상환 저축 (부채 감소) | B11: =IF(AND(COUNT(자산관리!E$9:E$23)>0,COUNT(자산관리!D$9:D$23)>0),MAX(0,자산관리!D$29-자산관리!E$29),0) -> 1200000
A12: 저축률 | B12: =IF(B5=0,0,B9/B5) -> 0.67668394
A14: 구분(1차) | B14: 항목(2차) | C14: 금액 | D14: 메모
A15: 수입 | B15: 참월급 | C15: 6000000
A16: 수입 | B16: 정윤월급 | C16: 3150000
A17: 수입 | B17: 기타수입 | C17: 500000
A18: 고정비 | B18: 주거비 | C18: 1250000
A19: 고정비 | B19: 용돈 | C19: 600000
A20: 고정비 | B20: 관리비 | C20: 210000
A21: 고정비 | B21: 통신 | C21: 120000
A22: 변동비 | B22: 할부금 | C22: 300000
A23: 변동비 | B23: 생활비 | C23: 1520000
A24: 변동비 | B24: 초과금 | C24: 100000
A25: 변동비 | B25: 의료비 | C25: 0
A26: 변동비 | B26: 기타 | C26: 220000
A27: ▲ 항목 추가 시 이 행 위에 행 삽입

Sheet 3월
A1: =설정!$B$4&"년 3월 가계부" -> 2025년 3월 가계부
A2: 노란 칸에 금액을 입력하세요. 저축 합계 = 일반 저축(수입 − 지출) + 대출상환 저축(자산관리 시트 부채 감소분, 자동)
A4: 요약 | B4: 금액 | D4: 그래프 데이터
A5: 총 수입 | B5: =SUMIF($A$15:$A$27,"수입",$C$15:$C$27) -> 7150000 | D5: 고정비 | E5: =B7 -> 2240000
A6: 총 지출 | B6: =B7+B8 -> 4400000 | D6: 변동비 | E6: =B8 -> 2160000
A7: 고정비 | B7: =SUMIF($A$15:$A$27,"고정비",$C$15:$C$27) -> 2240000 | D7: 일반저축 | E7: =MAX(B10,0) -> 2750000
A8: 변동비 | B8: =SUMIF($A$15:$A$27,"변동비",$C$15:$C$27) -> 2160000
A9: 저축 합계 | B9: =B10+B11 -> 3950000 | D9: 일반 저축 | E9: =MAX(B10,0) -> 2750000
A10: 일반 저축 (수입−지출) | B10: =B5-B6 -> 2750000 | D10: 대출상환 저축 | E10: =B11 -> 1200000
A11: 대출상환 저축 (부채 감소) | B11: =IF(AND(COUNT(자산관리!F$9:F$23)>0,COUNT(자산관리!E$9:E$23)>0),MAX(0,자산관리!E$29-자산관리!F$29),0) -> 1200000
A12: 저축률 | B12: =IF(B5=0,0,B9/B5) -> 0.55244755
A14: 구분(1차) | B14: 항목(2차) | C14: 금액 | D14: 메모
A15: 수입 | B15: 참월급 | C15: 4000000
A16: 수입 | B16: 정윤월급 | C16: 3150000
A17: 수입 | B17: 기타수입 | C17: 0
A18: 고정비 | B18: 주거비 | C18: 1250000
A19: 고정비 | B19: 용돈 | C19: 600000
A20: 고정비 | B20: 관리비 | C20: 270000
A21: 고정비 | B21: 통신 | C21: 120000
A22: 변동비 | B22: 할부금 | C22: 300000
A23: 변동비 | B23: 생활비 | C23: 1680000
A24: 변동비 | B24: 초과금 | C24: 100000
A25: 변동비 | B25: 의료비 | C25: 0
A26: 변동비 | B26: 기타 | C26: 80000
A27: ▲ 항목 추가 시 이 행 위에 행 삽입

Sheet 4월
A1: =설정!$B$4&"년 4월 가계부" -> 2025년 4월 가계부
A2: 노란 칸에 금액을 입력하세요. 저축 합계 = 일반 저축(수입 − 지출) + 대출상환 저축(자산관리 시트 부채 감소분, 자동)
A4: 요약 | B4: 금액 | D4: 그래프 데이터
A5: 총 수입 | B5: =SUMIF($A$15:$A$27,"수입",$C$15:$C$27) -> 7650000 | D5: 고정비 | E5: =B7 -> 2190000
A6: 총 지출 | B6: =B7+B8 -> 4340000 | D6: 변동비 | E6: =B8 -> 2150000
A7: 고정비 | B7: =SUMIF($A$15:$A$27,"고정비",$C$15:$C$27) -> 2190000 | D7: 일반저축 | E7: =MAX(B10,0) -> 3310000
A8: 변동비 | B8: =SUMIF($A$15:$A$27,"변동비",$C$15:$C$27) -> 2150000
A9: 저축 합계 | B9: =B10+B11 -> 4510000 | D9: 일반 저축 | E9: =MAX(B10,0) -> 3310000
A10: 일반 저축 (수입−지출) | B10: =B5-B6 -> 3310000 | D10: 대출상환 저축 | E10: =B11 -> 1200000
A11: 대출상환 저축 (부채 감소) | B11: =IF(AND(COUNT(자산관리!G$9:G$23)>0,COUNT(자산관리!F$9:F$23)>0),MAX(0,자산관리!F$29-자산관리!G$29),0) -> 1200000
A12: 저축률 | B12: =IF(B5=0,0,B9/B5) -> 0.58954248
A14: 구분(1차) | B14: 항목(2차) | C14: 금액 | D14: 메모
A15: 수입 | B15: 참월급 | C15: 4000000
A16: 수입 | B16: 정윤월급 | C16: 3150000
A17: 수입 | B17: 기타수입 | C17: 500000
A18: 고정비 | B18: 주거비 | C18: 1250000
A19: 고정비 | B19: 용돈 | C19: 600000
A20: 고정비 | B20: 관리비 | C20: 220000
A21: 고정비 | B21: 통신 | C21: 120000
A22: 변동비 | B22: 할부금 | C22: 300000
A23: 변동비 | B23: 생활비 | C23: 1310000
A24: 변동비 | B24: 초과금 | C24: 300000
A25: 변동비 | B25: 의료비 | C25: 0
A26: 변동비 | B26: 기타 | C26: 240000
A27: ▲ 항목 추가 시 이 행 위에 행 삽입

Sheet 5월
A1: =설정!$B$4&"년 5월 가계부" -> 2025년 5월 가계부
A2: 노란 칸에 금액을 입력하세요. 저축 합계 = 일반 저축(수입 − 지출) + 대출상환 저축(자산관리 시트 부채 감소분, 자동)
A4: 요약 | B4: 금액 | D4: 그래프 데이터
A5: 총 수입 | B5: =SUMIF($A$15:$A$27,"수입",$C$15:$C$27) -> 7650000 | D5: 고정비 | E5: =B7 -> 2260000
A6: 총 지출 | B6: =B7+B8 -> 4220000 | D6: 변동비 | E6: =B8 -> 1960000
A7: 고정비 | B7: =SUMIF($A$15:$A$27,"고정비",$C$15:$C$27) -> 2260000 | D7: 일반저축 | E7: =MAX(B10,0) -> 3430000
A8: 변동비 | B8: =SUMIF($A$15:$A$27,"변동비",$C$15:$C$27) -> 1960000
A9: 저축 합계 | B9: =B10+B11 -> 4630000 | D9: 일반 저축 | E9: =MAX(B10,0) -> 3430000
A10: 일반 저축 (수입−지출) | B10: =B5-B6 -> 3430000 | D10: 대출상환 저축 | E10: =B11 -> 1200000
A11: 대출상환 저축 (부채 감소) | B11: =IF(AND(COUNT(자산관리!H$9:H$23)>0,COUNT(자산관리!G$9:G$23)>0),MAX(0,자산관리!G$29-자산관리!H$29),0) -> 1200000
A12: 저축률 | B12: =IF(B5=0,0,B9/B5) -> 0.60522876
A14: 구분(1차) | B14: 항목(2차) | C14: 금액 | D14: 메모
A15: 수입 | B15: 참월급 | C15: 4000000
A16: 수입 | B16: 정윤월급 | C16: 3150000
A17: 수입 | B17: 기타수입 | C17: 500000
A18: 고정비 | B18: 주거비 | C18: 1250000
A19: 고정비 | B19: 용돈 | C19: 600000
A20: 고정비 | B20: 관리비 | C20: 290000
A21: 고정비 | B21: 통신 | C21: 120000
A22: 변동비 | B22: 할부금 | C22: 300000
A23: 변동비 | B23: 생활비 | C23: 1430000
A24: 변동비 | B24: 초과금 | C24: 100000
A25: 변동비 | B25: 의료비 | C25: 80000
A26: 변동비 | B26: 기타 | C26: 50000
A27: ▲ 항목 추가 시 이 행 위에 행 삽입

Sheet 6월
A1: =설정!$B$4&"년 6월 가계부" -> 2025년 6월 가계부
A2: 노란 칸에 금액을 입력하세요. 저축 합계 = 일반 저축(수입 − 지출) + 대출상환 저축(자산관리 시트 부채 감소분, 자동)
A4: 요약 | B4: 금액 | D4: 그래프 데이터
A5: 총 수입 | B5: =SUMIF($A$15:$A$27,"수입",$C$15:$C$27) -> 7150000 | D5: 고정비 | E5: =B7 -> 2290000
A6: 총 지출 | B6: =B7+B8 -> 4390000 | D6: 변동비 | E6: =B8 -> 2100000
A7: 고정비 | B7: =SUMIF($A$15:$A$27,"고정비",$C$15:$C$27) -> 2290000 | D7: 일반저축 | E7: =MAX(B10,0) -> 2760000
A8: 변동비 | B8: =SUMIF($A$15:$A$27,"변동비",$C$15:$C$27) -> 2100000
A9: 저축 합계 | B9: =B10+B11 -> 3950000 | D9: 일반 저축 | E9: =MAX(B10,0) -> 2760000
A10: 일반 저축 (수입−지출) | B10: =B5-B6 -> 2760000 | D10: 대출상환 저축 | E10: =B11 -> 1190000
A11: 대출상환 저축 (부채 감소) | B11: =IF(AND(COUNT(자산관리!I$9:I$23)>0,COUNT(자산관리!H$9:H$23)>0),MAX(0,자산관리!H$29-자산관리!I$29),0) -> 1190000
A12: 저축률 | B12: =IF(B5=0,0,B9/B5) -> 0.55244755
A14: 구분(1차) | B14: 항목(2차) | C14: 금액 | D14: 메모
A15: 수입 | B15: 참월급 | C15: 4000000
A16: 수입 | B16: 정윤월급 | C16: 3150000
A17: 수입 | B17: 기타수입 | C17: 0
A18: 고정비 | B18: 주거비 | C18: 1250000
A19: 고정비 | B19: 용돈 | C19: 600000
A20: 고정비 | B20: 관리비 | C20: 320000
A21: 고정비 | B21: 통신 | C21: 120000
A22: 변동비 | B22: 할부금 | C22: 300000
A23: 변동비 | B23: 생활비 | C23: 1380000
A24: 변동비 | B24: 초과금 | C24: 300000
A25: 변동비 | B25: 의료비 | C25: 0
A26: 변동비 | B26: 기타 | C26: 120000
A27: ▲ 항목 추가 시 이 행 위에 행 삽입

Sheet 7월
A1: =설정!$B$4&"년 7월 가계부" -> 2025년 7월 가계부
A2: 노란 칸에 금액을 입력하세요. 저축 합계 = 일반 저축(수입 − 지출) + 대출상환 저축(자산관리 시트 부채 감소분, 자동)
A4: 요약 | B4: 금액 | D4: 그래프 데이터
A5: 총 수입 | B5: =SUMIF($A$15:$A$27,"수입",$C$15:$C$27) -> 7650000 | D5: 고정비 | E5: =B7 -> 2180000
A6: 총 지출 | B6: =B7+B8 -> 4310000 | D6: 변동비 | E6: =B8 -> 2130000
A7: 고정비 | B7: =SUMIF($A$15:$A$27,"고정비",$C$15:$C$27) -> 2180000 | D7: 일반저축 | E7: =MAX(B10,0) -> 3340000
A8: 변동비 | B8: =SUMIF($A$15:$A$27,"변동비",$C$15:$C$27) -> 2130000
A9: 저축 합계 | B9: =B10+B11 -> 4550000 | D9: 일반 저축 | E9: =MAX(B10,0) -> 3340000
A10: 일반 저축 (수입−지출) | B10: =B5-B6 -> 3340000 | D10: 대출상환 저축 | E10: =B11 -> 1210000
A11: 대출상환 저축 (부채 감소) | B11: =IF(AND(COUNT(자산관리!J$9:J$23)>0,COUNT(자산관리!I$9:I$23)>0),MAX(0,자산관리!I$29-자산관리!J$29),0) -> 1210000
A12: 저축률 | B12: =IF(B5=0,0,B9/B5) -> 0.59477124
A14: 구분(1차) | B14: 항목(2차) | C14: 금액 | D14: 메모
A15: 수입 | B15: 참월급 | C15: 4000000
A16: 수입 | B16: 정윤월급 | C16: 3150000
A17: 수입 | B17: 기타수입 | C17: 500000
A18: 고정비 | B18: 주거비 | C18: 1250000
A19: 고정비 | B19: 용돈 | C19: 600000
A20: 고정비 | B20: 관리비 | C20: 210000
A21: 고정비 | B21: 통신 | C21: 120000
A22: 변동비 | B22: 할부금 | C22: 300000
A23: 변동비 | B23: 생활비 | C23: 1500000
A24: 변동비 | B24: 초과금 | C24: 100000
A25: 변동비 | B25: 의료비 | C25: 80000
A26: 변동비 | B26: 기타 | C26: 150000
A27: ▲ 항목 추가 시 이 행 위에 행 삽입

Sheet 8월
A1: =설정!$B$4&"년 8월 가계부" -> 2025년 8월 가계부
A2: 노란 칸에 금액을 입력하세요. 저축 합계 = 일반 저축(수입 − 지출) + 대출상환 저축(자산관리 시트 부채 감소분, 자동)
A4: 요약 | B4: 금액 | D4: 그래프 데이터
A5: 총 수입 | B5: =SUMIF($A$15:$A$27,"수입",$C$15:$C$27) -> 7150000 | D5: 고정비 | E5: =B7 -> 2280000
A6: 총 지출 | B6: =B7+B8 -> 4150000 | D6: 변동비 | E6: =B8 -> 1870000
A7: 고정비 | B7: =SUMIF($A$15:$A$27,"고정비",$C$15:$C$27) -> 2280000 | D7: 일반저축 | E7: =MAX(B10,0) -> 3000000
A8: 변동비 | B8: =SUMIF($A$15:$A$27,"변동비",$C$15:$C$27) -> 1870000
A9: 저축 합계 | B9: =B10+B11 -> 4200000 | D9: 일반 저축 | E9: =MAX(B10,0) -> 3000000
A10: 일반 저축 (수입−지출) | B10: =B5-B6 -> 3000000 | D10: 대출상환 저축 | E10: =B11 -> 1200000
A11: 대출상환 저축 (부채 감소) | B11: =IF(AND(COUNT(자산관리!K$9:K$23)>0,COUNT(자산관리!J$9:J$23)>0),MAX(0,자산관리!J$29-자산관리!K$29),0) -> 1200000
A12: 저축률 | B12: =IF(B5=0,0,B9/B5) -> 0.58741259
A14: 구분(1차) | B14: 항목(2차) | C14: 금액 | D14: 메모
A15: 수입 | B15: 참월급 | C15: 4000000
A16: 수입 | B16: 정윤월급 | C16: 3150000
A17: 수입 | B17: 기타수입 | C17: 0
A18: 고정비 | B18: 주거비 | C18: 1250000
A19: 고정비 | B19: 용돈 | C19: 600000
A20: 고정비 | B20: 관리비 | C20: 310000
A21: 고정비 | B21: 통신 | C21: 120000
A22: 변동비 | B22: 할부금 | C22: 300000
A23: 변동비 | B23: 생활비 | C23: 1430000
A24: 변동비 | B24: 초과금 | C24: 0
A25: 변동비 | B25: 의료비 | C25: 0
A26: 변동비 | B26: 기타 | C26: 140000
A27: ▲ 항목 추가 시 이 행 위에 행 삽입

Sheet 9월
A1: =설정!$B$4&"년 9월 가계부" -> 2025년 9월 가계부
A2: 노란 칸에 금액을 입력하세요. 저축 합계 = 일반 저축(수입 − 지출) + 대출상환 저축(자산관리 시트 부채 감소분, 자동)
A4: 요약 | B4: 금액 | D4: 그래프 데이터
A5: 총 수입 | B5: =SUMIF($A$15:$A$27,"수입",$C$15:$C$27) -> 9350000 | D5: 고정비 | E5: =B7 -> 2250000
A6: 총 지출 | B6: =B7+B8 -> 4910000 | D6: 변동비 | E6: =B8 -> 2660000
A7: 고정비 | B7: =SUMIF($A$15:$A$27,"고정비",$C$15:$C$27) -> 2250000 | D7: 일반저축 | E7: =MAX(B10,0) -> 4440000
A8: 변동비 | B8: =SUMIF($A$15:$A$27,"변동비",$C$15:$C$27) -> 2660000
A9: 저축 합계 | B9: =B10+B11 -> 5640000 | D9: 일반 저축 | E9: =MAX(B10,0) -> 4440000
A10: 일반 저축 (수입−지출) | B10: =B5-B6 -> 4440000 | D10: 대출상환 저축 | E10: =B11 -> 1200000
A11: 대출상환 저축 (부채 감소) | B11: =IF(AND(COUNT(자산관리!L$9:L$23)>0,COUNT(자산관리!K$9:K$23)>0),MAX(0,자산관리!K$29-자산관리!L$29),0) -> 1200000
A12: 저축률 | B12: =IF(B5=0,0,B9/B5) -> 0.60320856
A14: 구분(1차) | B14: 항목(2차) | C14: 금액 | D14: 메모
A15: 수입 | B15: 참월급 | C15: 6000000
A16: 수입 | B16: 정윤월급 | C16: 3150000
A17: 수입 | B17: 기타수입 | C17: 200000
A18: 고정비 | B18: 주거비 | C18: 1250000
A19: 고정비 | B19: 용돈 | C19: 600000
A20: 고정비 | B20: 관리비 | C20: 280000
A21: 고정비 | B21: 통신 | C21: 120000
A22: 변동비 | B22: 할부금 | C22: 300000
A23: 변동비 | B23: 생활비 | C23: 1750000
A24: 변동비 | B24: 초과금 | C24: 300000
A25: 변동비 | B25: 의료비 | C25: 80000
A26: 변동비 | B26: 기타 | C26: 230000
A27: ▲ 항목 추가 시 이 행 위에 행 삽입

Sheet 10월
A1: =설정!$B$4&"년 10월 가계부" -> 2025년 10월 가계부
A2: 노란 칸에 금액을 입력하세요. 저축 합계 = 일반 저축(수입 − 지출) + 대출상환 저축(자산관리 시트 부채 감소분, 자동)
A4: 요약 | B4: 금액 | D4: 그래프 데이터
A5: 총 수입 | B5: =SUMIF($A$15:$A$27,"수입",$C$15:$C$27) -> 7150000 | D5: 고정비 | E5: =B7 -> 2290000
A6: 총 지출 | B6: =B7+B8 -> 4460000 | D6: 변동비 | E6: =B8 -> 2170000
A7: 고정비 | B7: =SUMIF($A$15:$A$27,"고정비",$C$15:$C$27) -> 2290000 | D7: 일반저축 | E7: =MAX(B10,0) -> 2690000
A8: 변동비 | B8: =SUMIF($A$15:$A$27,"변동비",$C$15:$C$27) -> 2170000
A9: 저축 합계 | B9: =B10+B11 -> 3890000 | D9: 일반 저축 | E9: =MAX(B10,0) -> 2690000
A10: 일반 저축 (수입−지출) | B10: =B5-B6 -> 2690000 | D10: 대출상환 저축 | E10: =B11 -> 1200000
A11: 대출상환 저축 (부채 감소) | B11: =IF(AND(COUNT(자산관리!M$9:M$23)>0,COUNT(자산관리!L$9:L$23)>0),MAX(0,자산관리!L$29-자산관리!M$29),0) -> 1200000
A12: 저축률 | B12: =IF(B5=0,0,B9/B5) -> 0.54405594
A14: 구분(1차) | B14: 항목(2차) | C14: 금액 | D14: 메모
A15: 수입 | B15: 참월급 | C15: 4000000
A16: 수입 | B16: 정윤월급 | C16: 3150000
A17: 수입 | B17: 기타수입 | C17: 0
A18: 고정비 | B18: 주거비 | C18: 1250000
A19: 고정비 | B19: 용돈 | C19: 600000
A20: 고정비 | B20: 관리비 | C20: 320000
A21: 고정비 | B21: 통신 | C21: 120000
A22: 변동비 | B22: 할부금 | C22: 300000
A23: 변동비 | B23: 생활비 | C23: 1680000
A24: 변동비 | B24: 초과금 | C24: 0
A25: 변동비 | B25: 의료비 | C25: 0
A26: 변동비 | B26: 기타 | C26: 190000
A27: ▲ 항목 추가 시 이 행 위에 행 삽입

Sheet 11월
A1: =설정!$B$4&"년 11월 가계부" -> 2025년 11월 가계부
A2: 노란 칸에 금액을 입력하세요. 저축 합계 = 일반 저축(수입 − 지출) + 대출상환 저축(자산관리 시트 부채 감소분, 자동)
A4: 요약 | B4: 금액 | D4: 그래프 데이터
A5: 총 수입 | B5: =SUMIF($A$15:$A$27,"수입",$C$15:$C$27) -> 7650000 | D5: 고정비 | E5: =B7 -> 2230000
A6: 총 지출 | B6: =B7+B8 -> 4310000 | D6: 변동비 | E6: =B8 -> 2080000
A7: 고정비 | B7: =SUMIF($A$15:$A$27,"고정비",$C$15:$C$27) -> 2230000 | D7: 일반저축 | E7: =MAX(B10,0) -> 3340000
A8: 변동비 | B8: =SUMIF($A$15:$A$27,"변동비",$C$15:$C$27) -> 2080000
A9: 저축 합계 | B9: =B10+B11 -> 4540000 | D9: 일반 저축 | E9: =MAX(B10,0) -> 3340000
A10: 일반 저축 (수입−지출) | B10: =B5-B6 -> 3340000 | D10: 대출상환 저축 | E10: =B11 -> 1200000
A11: 대출상환 저축 (부채 감소) | B11: =IF(AND(COUNT(자산관리!N$9:N$23)>0,COUNT(자산관리!M$9:M$23)>0),MAX(0,자산관리!M$29-자산관리!N$29),0) -> 1200000
A12: 저축률 | B12: =IF(B5=0,0,B9/B5) -> 0.59346405
A14: 구분(1차) | B14: 항목(2차) | C14: 금액 | D14: 메모
A15: 수입 | B15: 참월급 | C15: 4000000
A16: 수입 | B16: 정윤월급 | C16: 3150000
A17: 수입 | B17: 기타수입 | C17: 500000
A18: 고정비 | B18: 주거비 | C18: 1250000
A19: 고정비 | B19: 용돈 | C19: 600000
A20: 고정비 | B20: 관리비 | C20: 260000
A21: 고정비 | B21: 통신 | C21: 120000
A22: 변동비 | B22: 할부금 | C22: 300000
A23: 변동비 | B23: 생활비 | C23: 1510000
A24: 변동비 | B24: 초과금 | C24: 100000
A25: 변동비 | B25: 의료비 | C25: 30000
A26: 변동비 | B26: 기타 | C26: 140000
A27: ▲ 항목 추가 시 이 행 위에 행 삽입

Sheet 12월
A1: =설정!$B$4&"년 12월 가계부" -> 2025년 12월 가계부
A2: 노란 칸에 금액을 입력하세요. 저축 합계 = 일반 저축(수입 − 지출) + 대출상환 저축(자산관리 시트 부채 감소분, 자동)
A4: 요약 | B4: 금액 | D4: 그래프 데이터
A5: 총 수입 | B5: =SUMIF($A$15:$A$27,"수입",$C$15:$C$27) -> 7650000 | D5: 고정비 | E5: =B7 -> 2230000
A6: 총 지출 | B6: =B7+B8 -> 4500000 | D6: 변동비 | E6: =B8 -> 2270000
A7: 고정비 | B7: =SUMIF($A$15:$A$27,"고정비",$C$15:$C$27) -> 2230000 | D7: 일반저축 | E7: =MAX(B10,0) -> 3150000
A8: 변동비 | B8: =SUMIF($A$15:$A$27,"변동비",$C$15:$C$27) -> 2270000
A9: 저축 합계 | B9: =B10+B11 -> 4350000 | D9: 일반 저축 | E9: =MAX(B10,0) -> 3150000
A10: 일반 저축 (수입−지출) | B10: =B5-B6 -> 3150000 | D10: 대출상환 저축 | E10: =B11 -> 1200000
A11: 대출상환 저축 (부채 감소) | B11: =IF(AND(COUNT(자산관리!O$9:O$23)>0,COUNT(자산관리!N$9:N$23)>0),MAX(0,자산관리!N$29-자산관리!O$29),0) -> 1200000
A12: 저축률 | B12: =IF(B5=0,0,B9/B5) -> 0.56862745
A14: 구분(1차) | B14: 항목(2차) | C14: 금액 | D14: 메모
A15: 수입 | B15: 참월급 | C15: 4000000
A16: 수입 | B16: 정윤월급 | C16: 3150000
A17: 수입 | B17: 기타수입 | C17: 500000
A18: 고정비 | B18: 주거비 | C18: 1250000
A19: 고정비 | B19: 용돈 | C19: 600000
A20: 고정비 | B20: 관리비 | C20: 260000
A21: 고정비 | B21: 통신 | C21: 120000
A22: 변동비 | B22: 할부금 | C22: 300000
A23: 변동비 | B23: 생활비 | C23: 1610000
A24: 변동비 | B24: 초과금 | C24: 100000
A25: 변동비 | B25: 의료비 | C25: 30000
A26: 변동비 | B26: 기타 | C26: 230000
A27: ▲ 항목 추가 시 이 행 위에 행 삽입

Sheet 설정
A1: 설정 · 항목 관리
A2: 파란 글씨·노란 칸이 직접 입력하는 칸입니다. 항목을 추가·삭제하면 각 시트의 드롭다운 목록에 반영됩니다.
A4: 기준 연도 | B4: 2025
A5: 전년 12월 말 부채 | C5: ← 1월 대출 상환액 계산용 (작년 12월 자산관리 시트의 부채 합계). 비워 두면 1월 상환액은 0
A6: 가계부 항목 | E6: 자산 분류 | I6: 사용 방법
A7: 구분(1차) | B7: 항목(2차) | E7: 대분류 | F7: 중분류 | G7: 소분류 | I7: 1) 매달 'N월' 시트의 금액 칸에 입력하면 합계·저축·그래프가 자동 계산됩니다.
A8: 수입 | B8: 참월급 | E8: 유동자산 | F8: 저축 | G8: 현금 | I8: 2) 가계부 항목 추가: 해당 월 시트의 '▲ 이 행 위에 삽입' 행 위에 행을 넣고 구분/항목/금액 입력.
A9: 수입 | B9: 정윤월급 | E9: 유동자산 | F9: 저축 | G9: 복지포인트 | I9: 항목 삭제: 그 행을 통째로 삭제. 구분은 반드시 수입·고정비·변동비 중 하나.
A10: 수입 | B10: 기타수입 | E10: 유동자산 | F10: 저축 | G10: 예비현금 | I10: 3) 자산 항목 추가/삭제도 '자산관리' 시트의 '▲ 이 행 위에 삽입' 행 기준으로 동일하게 합니다.
A11: 고정비 | B11: 주거비 | E11: 유동자산 | F11: 투자 | G11: 참주식 | I11: 대분류는 반드시 유동자산·비유동자산·부채 중 하나.
A12: 고정비 | B12: 용돈 | E12: 유동자산 | F12: 투자 | G12: 정윤주식 | I12: 4) 부채는 양수로 입력하세요 (예: 대출 잔액 300,000,000).
A13: 고정비 | B13: 관리비 | E13: 유동자산 | F13: 투자 | G13: 비트코인 | I13: 저축은 두 가지로 나눠 관리합니다: 일반 저축 = 수입 − 지출, 대출상환 저축 = 자산관리 시트 부채 합계가 전월보다 줄어든 만큼(자동).
A14: 고정비 | B14: 통신 | E14: 비유동자산 | F14: 부동산 | G14: 아파트 | I14: 5) 이 설정 시트의 목록은 드롭다운 후보입니다. 새 항목은 여기에도 적어두면 편합니다.
A15: 변동비 | B15: 할부금 | E15: 비유동자산 | F15: 퇴직금 | G15: 참퇴직금 | I15: 6) 1~3월 값은 예시입니다. 실제 금액으로 덮어쓰거나 지우세요.
A16: 변동비 | B16: 생활비 | E16: 비유동자산 | F16: 퇴직금 | G16: 정윤퇴직금 | I16: 7) 앱은 시트 이름(1월~12월, 자산관리)과 '구분'/'대분류' 머리글을 기준으로 읽습니다. 이름은 바꾸지 마세요.
A17: 변동비 | B17: 초과금 | E17: 비유동자산 | F17: 청약 | G17: 참청약
A18: 변동비 | B18: 의료비 | E18: 비유동자산 | F18: 청약 | G18: 정윤청약
A19: 변동비 | B19: 기타 | E19: 부채 | F19: 대출 | G19: 주택담보대출
E20: 부채 | F20: 대출 | G20: 신용대출
E21: 부채 | F21: 대출 | G21: 사내대출
